Workbook

Sheet Bill of exchange
A3: Zaber & Zubair Accessories Ltd.
A4: Mawna, Sreepur, Gazipur.
A6: Drawn under Letter of Credit No. 2979260400625 Dated 21.04.2026 of Shahjalal Islami Bank Plc., CTSD - Gulshan Hub, | K6: Drawn under Letter of Credit No:
A7: Devotech Technology park ltd. (3rd & 4th Floor), House No. 11, Road No. 113/A, Gulshan-2, Dhaka, Bangladesh. | K7: Applicant Bank:
K8: Applicant Name:
K9: Exchange Value:
K10: Lc Tenor:
K11: in word:
K12: Export Sales Contract No:
A13: Exchange for USD 8,123.98 Date: 28.04.2026 | K13: Applicants IRC No:
K14: Applicants TIN No:
A15: At 120 Days of this First of exchange (Second of the same tenor unpaid) please pay to the order of National Credit & Commerce Bank LTD Motijheel main Branch, 6 Motijheel C/A Dhaka-1000 Bangladesh. The same of USD: Eight thousand one hundred twenty three & cents ninety eight only. Export Sales Contract No. LIZ-LAMOUR-020-2026 Dated 31.03.2026, Applicants IRC No. 260326120008019,Applicants TIN No. 124958274887, Applicants Vat/bin No. 000226672-0103, Applicants Bank Bin No. 000443918-0101, Bond License no. 2238/CUS-SBW/1997, Beneficiary's Vat/Bin: 000230256-0103 and H.S Code No: 4819.10.00. | K15: Applicants Vat/bin No:
A16: Value Received | K16: Applicants Bank Bin No:
K17: Bond License no:
K18: Beneficiary's Vat/Bin:
K19: H.S Code No:
A21: To
A22: Shahjalal Islami Bank Plc.
A23: CTSD - Gulshan Hub, Devotech Technology park ltd. (3rd & 4th Floor),
A24: House No. 11, Road No. 113/A, Gulshan-2, Dhaka, Bangladesh.
H31: Authorized signature
A32: LIZ Fashion Industry Ltd
A33: H-1,BG-2,Block-C, Shaheed Mosharof Hossain RD,
A34: Purba Chandra, Shafipur, Kaliakoir, Gazipur.
A39: Zaber & Zubair Accessories Ltd.
A40: Mawna, Sreepur, Gazipur.
A42: =A6 -> Drawn under Letter of Credit No. 2979260400625 Dated 21.04.2026 of Shahjalal Islami Bank Plc., CTSD - Gulshan Hub,
A43: =A7 -> Devotech Technology park ltd. (3rd & 4th Floor), House No. 11, Road No. 113/A, Gulshan-2, Dhaka, Bangladesh.
A49: =A13 -> Exchange for USD 8,123.98 Date: 28.04.2026
A51: At 120 Days of this Second of exchange (First of the same tenor unpaid) please pay to the order of National Credit & Commerce Bank LTD Motijheel main Branch, 6 Motijheel C/A Dhaka-1000 Bangladesh. The same of USD: Eight thousand one hundred twenty three & cents ninety eight only. Export Sales Contract No. LIZ-LAMOUR-020-2026 Dated 31.03.2026, Applicants IRC No. 260326120008019,Applicants TIN No. 124958274887, Applicants Vat/bin No. 000226672-0103, Applicants Bank Bin No. 000443918-0101, Bond License no. 2238/CUS-SBW/1997, Beneficiary's Vat/Bin: 000230256-0103 and H.S Code No: 4819.10.00.
A52: Value Received
A57: To
A58: =A22 -> Shahjalal Islami Bank Plc.
A59: =A23 -> CTSD - Gulshan Hub, Devotech Technology park ltd. (3rd & 4th Floor),
A60: =A24 -> House No. 11, Road No. 113/A, Gulshan-2, Dhaka, Bangladesh.
A68: Authorized signature
A69: =A32 -> LIZ Fashion Industry Ltd
A70: =A33 -> H-1,BG-2,Block-C, Shaheed Mosharof Hossain RD,
A71: =A34 -> Purba Chandra, Shafipur, Kaliakoir, Gazipur.

Sheet Commercial Invoice
A2: COMMERCIAL INVOICE
A3: Beneficiary | H3: Invoice No | I3: : ZZAL/PI/26/52017 | K3: Invoice No
A4: Zaber & Zubair Accessories Ltd. | H4: Date | I4: : 28.04.2026 | K4: Invoice Date
A5: H/O: 115-120 Motijheel. C/A, Dhaka-1000 bangladesh. | H5: L/C No | I5: : 2979260400625 | K5: L/C No
A6: Factory: Mawna, Sreepur, Gazipur. | H6: Dated | I6: : 21.04.2026 | K6: L/C Date
H7: Proforma | I7: : ZZAL/PI/26/52017,52015 | K7: Proforma Invoice No
A8: Advising Bank: | H8: Invoice | K8: L/C issuing
A9: National Credit & Commerce Bank LTD Motijheel main Branch, | H9: Dated | I9: : 13.04.2026 | K9: Place of Loading
A10: 6 Motijheel C/A Dhaka-1000 Bangladesh. | H10: L/C issuing | I10: : Shahjalal Islami Bank Plc. | K10: Place of Delivery
A11: Consignee | H11: Bank | I11: CTSD - Gulshan Hub, Devotech Technology park ltd.
A12: LIZ Fashion Industry Ltd | I12: (3rd & 4th Floor), House No. 11, Road No. 113/A, Gulshan-2,
A13: H-1,BG-2,Block-C, Shaheed Mosharof Hossain RD, | I13: Dhaka, Bangladesh.
A14: Purba Chandra, Shafipur, Kaliakoir, Gazipur.
H15: Place of | I15: :Supplier's factory
A16: Consignee's Bank | H16: Loading
A17: {='Bill of exchange'!A22:A24} -> Shahjalal Islami Bank Plc. | H17: Place of | I17: : Opener's factory
A18: CTSD - Gulshan Hub, Devotech Technology park ltd. (3rd & 4th Floor), | H18: Delivery | I18: : Bangladesh
A19: House No. 11, Road No. 113/A, Gulshan-2, Dhaka, Bangladesh. | I19: : By Truck
A20: SL NO. | B20: Description of Goods | H20: Quantity | I20: Price $ | J20: Amount $
A21: BUYER: LMR
A22: 1 | B22: Carton - 62x54x31 CM | G22: 5Ply | H22: 1096 | I22: 1.5776 | J22: =H22*I22 -> 1729.0496
A23: 2 | B23: Carton - 62x54x31 CM | G23: 5Ply | H23: 1096 | I23: 1.5776 | J23: =H23*I23 -> 1729.0496
A24: 3 | B24: Carton - 23''x10.5''x14'' | G24: 5ply | H24: 7036 | I24: 0.573331 | J24: =H24*I24 -> 4033.9569
A25: 4 | B25: Top Bottom - 22''x9.5'' | G25: 3ply | H25: 14074 | I25: 0.0449 | J25: =H25*I25 -> 631.9226
B26: Total= | H26: =SUM(H22:H25) -> 23302 | J26: =SUM(J22:J25) -> 8123.9787
A27: Freight prepaid
A28: Export Sales Contract No. LIZ-LAMOUR-020-2026 Dated 31.03.2026, Applicants IRC No. 260326120008019,Applicants TIN No. 124958274887, Applicants Vat/bin No. 000226672-0103, Applicants Bank Bin No. 000443918-0101, Bond License no. 2238/CUS-SBW/1997, Beneficiary's Vat/Bin: 000230256-0103 and H.S Code No: 4819.10.00. We hereby certify that the quantity, quality, rate, packing making & other details of the goods shipped are strictly in accordance with the terms of the proforma Invoice No. ZZAL/PI/26/52017,52015 Dated 13.04.2026 and terms & conditions related to the Proforma Invoice & L/C have been fully complied with.
A29: For Zaber & Zubair Accessories Ltd.
A35: Authorized signature

Sheet Packing List
A2: PACKING List
A3: Beneficiary | F3: Consignee
A4: Zaber & Zubair Accessories Ltd. | F4: LIZ Fashion Industry Ltd
A5: H/O: Adamjee Court Main Building (4th floor), 115-120 | F5: H-1,BG-2,Block-C, Shaheed Mosharof Hossain RD,
A6: Motijheel. C/A, Dhaka-1000 , Dhaka-1000 bangladesh. | F6: Purba Chandra, Shafipur, Kaliakoir, Gazipur.
A7: Factory: Mawna, Sreepur, Gazipur. | F7: Consignee's Bank
A8: Advising Bank: | F8: {='Commercial Invoice'!A17:A19} -> Shahjalal Islami Bank Plc.
A9: National Credit & Commerce Bank LTD | F9: CTSD - Gulshan Hub, Devotech Technology park ltd. (3rd & 4th Floor),
A10: Motijheel main Branch, 6 Motijheel C/A Dhaka-1000 Bangladesh. | F10: House No. 11, Road No. 113/A, Gulshan-2, Dhaka, Bangladesh.
A11: SL NO. | B11: Description of Goods | H11: Quantity
A12: ='Commercial Invoice'!A21 -> BUYER: LMR
A13: 1 | B13: Carton - 62x54x31 CM | G13: 5Ply | H13: 1096
A14: 2 | B14: Carton - 62x54x31 CM | G14: 5Ply | H14: 1096
A15: 3 | B15: Carton - 23''x10.5''x14'' | G15: 5ply | H15: 7036
A16: 4 | B16: Top Bottom - 22''x9.5'' | G16: 3ply | H16: 14074
B17: Total= | H17: =SUM(H13:H16) -> 23302
A18: Packing | C18: : Standard poly packing rolls | I18: Packing
A19: L/C No. | C19: : 2979260400625 Dated 21.04.2026. | I19: L/C No.
A20: Applicants IRC No. 260326120008019,Applicants TIN No. 124958274887, Applicants Vat/bin No. 000226672-0103, Applicants Bank Bin No. 000443918-0101, Bond License no. 2238/CUS-SBW/1997, Beneficiary's Vat/Bin: 000230256-0103 and H.S Code No: 4819.10.00. | I20: L/C Date
A21: Sales Contract No | C21: : LIZ-LAMOUR-020-2026 Dated 31.03.2026. | I21: Sales Contract No
A22: proforma Invoice | C22: : ZZAL/PI/26/52017,52015 Dated 13.04.2026. | I22: Carrier
A23: Carrier | C23: : By Truck
A24: For Zaber & Zubair Accessories Ltd. | F24: Goods recceived in good condition
A29: Authorized signature | F29: Signature of Consignee with Seal

Sheet Delivery Challan
A2: DELIVERY CHALLAN
A3: No: ZZAL/PI/26/52017 | F3: Date | G3: ='Commercial Invoice'!I4 -> : 28.04.2026
A4: Beneficiary | F4: Consignee
A5: Zaber & Zubair Accessories Ltd. | F5: LIZ Fashion Industry Ltd
A6: H/O: Adamjee Court Main Building (4th floor), 115-120 | F6: H-1,BG-2,Block-C, Shaheed Mosharof Hossain RD,
A7: Motijheel. C/A, Dhaka-1000 , Dhaka-1000 bangladesh. | F7: Purba Chandra, Shafipur, Kaliakoir, Gazipur.
A8: Factory: Mawna, Sreepur, Gazipur. | F8: Consignee's Bank
A9: Advising Bank: | F9: {='Packing List'!F8:F10} -> Shahjalal Islami Bank Plc.
A10: National Credit & Commerce Bank LTD | F10: CTSD - Gulshan Hub, Devotech Technology park ltd. (3rd & 4th Floor),
A11: Motijheel main Branch, 6 Motijheel C/A Dhaka-1000 Bangladesh. | F11: House No. 11, Road No. 113/A, Gulshan-2, Dhaka, Bangladesh.
A12: SL NO. | B12: Description of Goods | H12: Quantity
A13: ='Commercial Invoice'!A21 -> BUYER: LMR
A14: 1 | B14: Carton - 62x54x31 CM | G14: 5Ply | H14: 1096
A15: 2 | B15: Carton - 62x54x31 CM | G15: 5Ply | H15: 1096
A16: 3 | B16: Carton - 23''x10.5''x14'' | G16: 5ply | H16: 7036
A17: 4 | B17: Top Bottom - 22''x9.5'' | G17: 3ply | H17: 14074
B18: Total= | H18: =SUM(H14:H17) -> 23302
A19: Freight prepaid
A20: Packing | C20: ='Packing List'!C18 -> : Standard poly packing rolls | I20: Packing
A21: L/C No. | C21: ='Packing List'!C19 -> : 2979260400625 Dated 21.04.2026. | I21: L/C No.
A22: ='Packing List'!A20:H20 -> Applicants IRC No. 260326120008019,Applicants TIN No. 124958274887, Applicants Vat/bin No. 000226672-0103, Applicants Bank Bin No. 000443918-0101, Bond License no. 2238/CUS-SBW/1997, Beneficiary's Vat/Bin: 000230256-0103 and H.S Code No: 4819.10.00. | I22: L/C Date
A23: Export LC No | C23: ='Packing List'!C21 -> : LIZ-LAMOUR-020-2026 Dated 31.03.2026. | I23: Sales Contract No
A24: Proforma Invoice No | C24: ='Packing List'!C22 -> : ZZAL/PI/26/52017,52015 Dated 13.04.2026. | I24: Carrier
A25: Carrier | C25: ='Packing List'!C23 -> : By Truck
A27: For Zaber & Zubair Accessories Ltd. | F27: Goods recceived in good condition
A32: Authorized signature | F32: Signature of Consignee with Seal

Sheet Truck Challan
A2: TRUCK CHALLAN
A3: Beneficiary | F3: Consignee
A4: Zaber & Zubair Accessories Ltd. | F4: LIZ Fashion Industry Ltd
A5: H/O: 115-120 Motijheel. C/A, Dhaka-1000 bangladesh. | F5: H-1,BG-2,Block-C, Shaheed Mosharof Hossain RD,
A6: Factory: Mawna, Sreepur, Gazipur. | F6: Purba Chandra, Shafipur, Kaliakoir, Gazipur.
A7: Advising Bank: | F7: Consignee's Bank
A8: National Credit & Commerce Bank LTD Motijheel main Branch, | F8: {='Packing List'!F8:F10} -> Shahjalal Islami Bank Plc.
A9: 6 Motijheel C/A Dhaka-1000 Bangladesh. | F9: CTSD - Gulshan Hub, Devotech Technology park ltd. (3rd & 4th Floor),
F10: House No. 11, Road No. 113/A, Gulshan-2, Dhaka, Bangladesh.
A11: SL NO. | B11: Description of Goods | H11: Quantity/Cone
A12: ='Commercial Invoice'!A21 -> BUYER: LMR
A13: 1 | B13: Carton - 62x54x31 CM | G13: 5Ply | H13: 1096
A14: 2 | B14: Carton - 62x54x31 CM | G14: 5Ply | H14: 1096
A15: 3 | B15: Carton - 23''x10.5''x14'' | G15: 5ply | H15: 7036
A16: 4 | B16: Top Bottom - 22''x9.5'' | G16: 3ply | H16: 14074
B17: Total= | H17: =SUM(H13:H16) -> 23302
A18: Packing | C18: ='Packing List'!C18 -> : Standard poly packing rolls | I18: Packing
A19: L/C No. | C19: ='Packing List'!C19 -> : 2979260400625 Dated 21.04.2026. | I19: L/C No.
A20: ='Packing List'!A20:H20 -> Applicants IRC No. 260326120008019,Applicants TIN No. 124958274887, Applicants Vat/bin No. 000226672-0103, Applicants Bank Bin No. 000443918-0101, Bond License no. 2238/CUS-SBW/1997, Beneficiary's Vat/Bin: 000230256-0103 and H.S Code No: 4819.10.00. | I20: L/C Date
A21: Export LC No | C21: ='Packing List'!C21 -> : LIZ-LAMOUR-020-2026 Dated 31.03.2026. | I21: Sales Contract No
A22: Proforma Invoice No | C22: ='Packing List'!C22 -> : ZZAL/PI/26/52017,52015 Dated 13.04.2026. | I22: Carrier
A23: Carrier | C23: ='Packing List'!C23 -> : By Truck
A29: For Zaber & Zubair Accessories Ltd. | G29: Goods recceived in good condition
A34: Authorized signature | G34: Signature of Consignee with Seal

Sheet CERTIFICATE OF ORIGIN
A2: CERTIFICATE OF ORIGIN
A5: This is to certify that the goods, which are delivered under L/C No. 2979260400625 Dated 21.04.2026 as per Proforma Invoice No. ZZAL/PI/26/52017,52015 Dated 13.04.2026 is of Bangladesh Origin. | J5: Lc No
A6: ='Packing List'!A20:H20 -> Applicants IRC No. 260326120008019,Applicants TIN No. 124958274887, Applicants Vat/bin No. 000226672-0103, Applicants Bank Bin No. 000443918-0101, Bond License no. 2238/CUS-SBW/1997, Beneficiary's Vat/Bin: 000230256-0103 and H.S Code No: 4819.10.00. | J6: LC Date
J7: Export Sales Contract No:
A8: Sales Contract No | C8: ='Packing List'!C21 -> : LIZ-LAMOUR-020-2026 Dated 31.03.2026. | J8: Applicants IRC No:
J9: Applicants TIN No:
A10: For and of behalf of, | J10: Applicants Vat/bin No:
J11: Applicants Bank Bin No:
J12: Bond License no:
J13: Beneficiary's Vat/Bin:
J14: H.S Code No:
A18: For Zaber & Zubair Accessories Ltd.
A23: Authorized signature

Sheet BENEFICIARY’S CERTIFICATE
A2: BENEFICIARY’S CERTIFICATE | J2: export Qty
J3: export Vale
J4: pro-forma invoice No
A5: We hereby confirm that we have supplied Accessories for 100% export oriented garments industry: 23,302 cones / pes total amount of US $ 8,123.98 all other details as per pro-forma invoice No. ZZAL/PI/26/52017,52015 Dated 13.04.2026. To The LIZ Fashion Industry Ltd, H-1,BG-2,Block-C, Shaheed Mosharof Hossain RD,Purba Chandra, Shafipur, Kaliakoir, Gazipur. Against their Shahjalal Islami Bank Plc., CTSD - Gulshan Hub, Devotech Technology park ltd. (3rd & 4th Floor), House No. 11, Road No. 113/A, Gulshan-2, Dhaka, Bangladesh. L/C No. 2979260400625 Dated 21.04.2026 under Applicants IRC No. 260326120008019,Applicants TIN No. 124958274887, Applicants Vat/bin No. 000226672-0103, Applicants Bank Bin No. 000443918-0101, Bond License no. 2238/CUS-SBW/1997, Beneficiary's Vat/Bin: 000230256-0103 and H.S Code No: 4819.10.00. Sales Contract No: LIZ-LAMOUR-020-2026 Dated 31.03.2026 for exporting readymade garments.
A7: We do hereby undertake that the said accessories shipment from : Beneficiary’s factory to applicant factory warehouse. We also certified that quantity, quality, rate specification & all other terms & conditions are as per suppliers pro-forma invoice No . ZZAL/PI/26/52017,52015 Dated 13.04.2026 any short and defective goods to be replaced by us on free of cost.
J13: Lc No
J14: LC Date
A15: For & on behalf of | J15: Export Sales Contract No:
A16: For Zaber & Zubair Accessories Ltd. | J16: Applicants IRC No:
J17: Applicants TIN No:
J18: Applicants Vat/bin No:
J19: Applicants Bank Bin No:
A20: Authorized signature | J20: Bond License no:
J21: Beneficiary's Vat/Bin:
J22: H.S Code No:

Sheet Forwarding
A2: Date:
A3: Reference No.: ZZAL/PI/26/52017 | H3: Invoice No.
A4: To | H4: Advising Bank:
A5: The Manager | H5: Lc Value
A6: National Credit & Commerce Bank LTD Motijheel main Branch, | H6: Lc No
A7: 6 Motijheel C/A Dhaka-1000 Bangladesh. | H7: LC Date
H8: proforma Invoice No.
A10: Subject: Application for the following negotiation documents for US $ 8,123.98 Against
B11: Letter of Credit No. 2979260400625 Dated 21.04.2026 of LIZ Fashion Industry Ltd.
A13: Dear Sir,
A14: We hereby submit the following documents for negotiation of US $ 8,123.98 (United States Dollar
A15: Eight thousand one hundred twenty three & cents ninety eight only) delivery of garments accessories as per
A16: proforma Invoice No. ZZAL/PI/26/52017,52015 Dated 13.04.2026.
A18: SL | B18: Description | C18: Advising Bank | D18: Consignee's Bank
A19: 1 | B19: Bill of Exchange | C19: 2 Copies | D19: 2 Copies | H19: Bill of Exchange
A20: 2 | B20: Commercial Invoice | C20: 1 Copy | D20: 6 Copies | H20: Commercial Invoice
A21: 3 | B21: Packing List | C21: 1 Copy | D21: 3 Copies | H21: Packing List
A22: 4 | B22: Delivery Challan | C22: 1 Copy | D22: 3 Copies | H22: Delivery Challan
A23: 5 | B23: Certificate of Orgin | C23: 1 Copy | D23: 3 Copies | H23: Certificate of Orgin
A24: 6 | B24: Beneficiary Certificate | C24: 1 Copy | D24: 2 Copies | H24: Beneficiary Certificate
A25: 7 | B25: Truck Challan | C25: 1 Copy | D25: 2 Copies | H25: Truck Challan
A26: 8 | B26: Mushok Challan 6.3 | C26: 1 Copy | D26: 2 Copies
A27: 9 | B27: Others | C27: 0 Copy | D27: 0 Copy
A28: 10 | B28: Orginal L/C | C28: 1 Copy | D28: 0 Copy
A30: So we request you to negotiate the above stated matter as early as possible.
A32: Thanking you,
A33: Sincerely yours,
A34: For Zaber & Zubair Accessories Ltd.
A39: Authorized signature

Sheet Challan Sheet
A5: LIZ Fashion Industry Ltd
A6: Quality Certificate From | F6: Date: 04.06.2026 | J6: AS per ERP list
A7: PI NO | B7: Order Ref# | C7: Description | D7: Delivery Date | E7: Qty | F7: Challan No | G7: Inspection Result
A8: 26/52017 | B8: LIZ-LO-CTN-26030030-R1 | C8: Carton - 62x54x31 CM | D8: 09.03.2026 | E8: 94 | F8: 8043097
B9: LIZ-LO-CTN-26030030-R1 | C9: Carton - 62x54x31 CM | E9: 992 | F9: 8040075
B10: LIZ-LO-CTN-26030030-R1 | C10: Carton - 62x54x31 CM | D10: 10.03.2026 | E10: 10 | F10: 8044055
B11: LIZ-LO-CTN-26030031-R1 | C11: Carton - 62x54x31 CM | D11: 09.03.2026 | E11: 144 | F11: 8043096
B12: LIZ-LO-CTN-26030031-R1 | C12: Carton - 62x54x31 CM | E12: 950 | F12: 8040064
B13: LIZ-LO-CTN-26030031-R1 | C13: Carton - 62x54x31 CM | D13: 10.03.2026 | E13: 2 | F13: 8044054
A14: 26/52015 | B14: LIZ-LO-CTN-26020242 | C14: Carton - 23''x10.5''x11.5'' | D14: 15.03.2026 | E14: 485 | F14: 8295094
C15: Carton - 23''x10.5''x14'' | E15: 264
C16: Top Bottom - 22''x9.5'' | E16: 2492
C17: Carton - 23''x10.5''x14'' | D17: 30.03.2026 | E17: 475 | F17: 8519054
C18: Carton - 23''x10.5''x14'' | D18: 03.04.2026 | E18: 20 | F18: 8723065
C19: Carton - 23''x10.5''x11.5'' | E19: 3
B20: LIZ-LO-CTN-26020243 | C20: Carton - 22''x10''x10.5'' | D20: 15.03.2026 | E20: 253 | F20: 8295098
C21: Carton - 22''x10''x13.5'' | E21: 20
C22: Top Bottom - 21''x9'' | E22: 746
C23: Carton - 22''x10''x13.5'' | D23: 30.03.2026 | E23: 98 | F23: 8516054
B24: LIZ-LO-CTN-26020244 | C24: Carton - 23''x10.5''x10.5'' | D24: 06.04.2026 | E24: 318 | F24: 8799095
C25: Carton - 23''x10.5''x13'' | E25: 552
C26: Top Bottom - 22''x9.5'' | E26: 1776
C27: Carton - 23''x10.5''x10.5'' | D27: 03.04.2026 | E27: 13 | F27: 8799179
C28: Carton - 23''x10.5''x13'' | E28: 5
B29: LIZ-LO-CTN-26020245 | C29: Carton - 15''x10.5''x11.5'' | D29: 30.03.2026 | E29: 330 | F29: 8516057
C30: Carton - 15''x10.5''x11.5'' | D30: 03.04.2026 | E30: 1 | F30: 8723068
C31: Carton - 15''x10.5''x9.5'' | E31: 3
C32: Carton - 15''x10.5''x9.5'' | D32: 15.03.2026 | E32: 609 | F32: 8295104
C33: Top Bottom - 14''x9.5'' | E33: 1886
B34: LIZ-LO-CTN-26020246 | C34: Carton - 16''x9''x7'' | D34: 06.04.2026 | E34: 987 | F34: 8799120
C35: Carton - 16''x9''x8'' | E35: 583
C36: Top Bottom - 15.5''x8'' | E36: 3224
C37: Carton - 16''x9''x8'' | E37: 5 | F37: 8799181
C38: Carton - 16''x9''x7'' | E38: 37
B39: LIZ-LO-CTN-26020247 | C39: Carton - 15.5''x10.5''x8'' | D39: 30.03.2026 | E39: 539 | F39: 8518055
C40: Carton - 15.5''x10.5''x9'' | D40: 15.03.2026 | E40: 255 | F40: 8295108
C41: Top Bottom - 14.5''x9.5'' | E41: 1588
B42: LIZ-LO-CTN-26020248 | C42: Carton - 15''x10.5''x9'' | D42: 15.03.2026 | E42: 146 | F42: 8295111
C43: Carton - 15''x10.5''x11'' | E43: 397
C44: Top Bottom - 14''x9.5'' | E44: 1938
...
